Workbook

Sheet 환불표 ver.1
B1: 환불표
B3: ▶ 기간권 | H3: ▶ 시간권
B4: 종류 | C4: 상품금액 | D4: 사용일수 | E4: 주차 | F4: 환불금액 | H4: 종류 | I4: 상품금액 | J4: 이용시간 | K4: 환불금액
B5: 오픈행사 4주권 | C5: =VLOOKUP(B5,Sheet1!G5:H9,2,FALSE) -> 79000 | D5: 22 | E5: =ROUNDUP(D5/7,0) -> 4 | F5: =IFERROR(INDEX(Sheet1!E4:E143,MATCH(1,Sheet1!B4:B143,0)),0) -> 0 | H5: 오픈100시간권 | I5: =VLOOKUP(H5,Sheet1!S3:T5,2,FALSE) -> 69000 | J5: 9 | K5: =IFERROR(INDEX(Sheet1!Q3:Q232,MATCH(1,Sheet1!N3:N232,0)),0) -> 55500
B7: 앤딩 스터디카페 - 환불규정, 환불 테이블 사용법
B8: 환불규정 | H8: 환불테이블 사용법
B9: 아래 내용을 자세히 읽어보시고, 문의를 통해 알려주시면 환불 진행에 도움을 드리겠습니다. | H9: [기간권] | I9: 1.종류 탭에서 기간권 선택
I10: 2.'사용일수' 탭에 사용일 입력 -> 주차 계산
B11: [당일권] | I11: 3.환불금액 확인
B12: - 환불 불가 | H12: [시간권] | I12: 1.종류 탭에서 시간권 선택
I13: 2.'이용시간' 탭에 이용시간 입력
B14: [충전권] | I14: 3.환불금액 확인
B15: - 이용권 사용량에 따라 차감됩니다.
B16: - 시간당 1500원씩 차감 후 차액 환급
B17: - 구매 4주 후에는 환불 불가
B19: [스터디룸]
B20: - 환불 불가
B21: - 예약일정 변경만 가능
B23: [기간권 / 2주]
B24: - 사용 1주차 : 결제금액의 40% 환불
B25: - 사용 2주차 : 환불 불가
B27: [기간권 / 지정석 4주]
B28: - 사용 1주차 : 결제금액의 70% 환불
B29: - 사용 2주차 : 결제금액의 40% 환불
... B49: 약 2~4주 소요됩니다. (결제 당일건만 당일취소)

Sheet Sheet1
B2: 기간권 raw data | N2: 시간권 raw data
C3: 종류 | D3: 사용일수 | E3: 환불금액 | H3: 납부금액 | I3: 환불금액 | N3: =--($O$3:$O$232='환불표 ver.1'!$H$5)*($P$3:$P$232='환불표 ver.1'!$J$5) -> 0 | O3: 100시간권 | P3: 0 | Q3: 95000 | S3: 100시간권 | T3: 95000
B4: =--($C$4:$C$115='환불표 ver.1'!$B$5)*($D$4:$D$115='환불표 ver.1'!$D$5) -> 0 | C4: 2주권 | D4: 1 | E4: 22000 | I4: 1주일 | J4: 2주일 | K4: 3주일 | L4: 4주일 | N4: =--($O$3:$O$232='환불표 ver.1'!$H$5)*($P$3:$P$232='환불표 ver.1'!$J$5) -> 0 | O4: 100시간권 | P4: 1 | Q4: =Q3-1500 -> 93500 | S4: 200시간권 | T4: 180000
B5: =--($C$4:$C$115='환불표 ver.1'!$B$5)*($D$4:$D$115='환불표 ver.1'!$D$5) -> 0 | C5: 2주권 | D5: 2 | E5: 22000 | G5: 2주권 | H5: 55000 | I5: 22000 | J5: 0 | K5: 0 | L5: 0 | N5: =--($O$3:$O$232='환불표 ver.1'!$H$5)*($P$3:$P$232='환불표 ver.1'!$J$5) -> 0 | O5: 100시간권 | P5: 2 | Q5: =Q4-1500 -> 92000 | S5: 오픈100시간권 | T5: 69000
B6: =--($C$4:$C$115='환불표 ver.1'!$B$5)*($D$4:$D$115='환불표 ver.1'!$D$5) -> 0 | C6: 2주권 | D6: 3 | E6: 22000 | G6: 4주권 | H6: 119000 | I6: 83300 | J6: 47600 | K6: 23800 | L6: 0 | N6: =--($O$3:$O$232='환불표 ver.1'!$H$5)*($P$3:$P$232='환불표 ver.1'!$J$5) -> 0 | O6: 100시간권 | P6: 3 | Q6: =Q5-1500 -> 90500
B7: =--($C$4:$C$115='환불표 ver.1'!$B$5)*($D$4:$D$115='환불표 ver.1'!$D$5) -> 0 | C7: 2주권 | D7: 4 | E7: 22000 | G7: 고정석 4주권 | H7: 179000 | I7: 125300 | J7: 71600 | K7: 35800 | L7: 0 | N7: =--($O$3:$O$232='환불표 ver.1'!$H$5)*($P$3:$P$232='환불표 ver.1'!$J$5) -> 0 | O7: 100시간권 | P7: 4 | Q7: =Q6-1500 -> 89000
B8: =--($C$4:$C$115='환불표 ver.1'!$B$5)*($D$4:$D$115='환불표 ver.1'!$D$5) -> 0 | C8: 2주권 | D8: 5 | E8: 22000 | G8: 관리고정석 4주권 | H8: 229000 | I8: 160300 | J8: 91600 | K8: 45800 | L8: 0 | N8: =--($O$3:$O$232='환불표 ver.1'!$H$5)*($P$3:$P$232='환불표 ver.1'!$J$5) -> 0 | O8: 100시간권 | P8: 5 | Q8: =Q7-1500 -> 87500
B9: =--($C$4:$C$115='환불표 ver.1'!$B$5)*($D$4:$D$115='환불표 ver.1'!$D$5) -> 0 | C9: 2주권 | D9: 6 | E9: 22000 | G9: 오픈행사 4주권 | H9: 79000 | I9: 55300 | J9: 31600 | K9: 15800 | L9: 0 | N9: =--($O$3:$O$232='환불표 ver.1'!$H$5)*($P$3:$P$232='환불표 ver.1'!$J$5) -> 0 | O9: 100시간권 | P9: 6 | Q9: =Q8-1500 -> 86000
B10: =--($C$4:$C$115='환불표 ver.1'!$B$5)*($D$4:$D$115='환불표 ver.1'!$D$5) -> 0 | C10: 2주권 | D10: 7 | E10: 22000 | N10: =--($O$3:$O$232='환불표 ver.1'!$H$5)*($P$3:$P$232='환불표 ver.1'!$J$5) -> 0 | O10: 100시간권 | P10: 7 | Q10: =Q9-1500 -> 84500
B11: =--($C$4:$C$115='환불표 ver.1'!$B$5)*($D$4:$D$115='환불표 ver.1'!$D$5) -> 0 | C11: 2주권 | D11: 8 | E11: 0 | N11: =--($O$3:$O$232='환불표 ver.1'!$H$5)*($P$3:$P$232='환불표 ver.1'!$J$5) -> 0 | O11: 100시간권 | P11: 8 | Q11: =Q10-1500 -> 83000
B12: =--($C$4:$C$115='환불표 ver.1'!$B$5)*($D$4:$D$115='환불표 ver.1'!$D$5) -> 0 | C12: 2주권 | D12: 9 | E12: 0 | N12: =--($O$3:$O$232='환불표 ver.1'!$H$5)*($P$3:$P$232='환불표 ver.1'!$J$5) -> 0 | O12: 100시간권 | P12: 9 | Q12: =Q11-1500 -> 81500
B13: =--($C$4:$C$115='환불표 ver.1'!$B$5)*($D$4:$D$115='환불표 ver.1'!$D$5) -> 0 | C13: 2주권 | D13: 10 | E13: 0 | N13: =--($O$3:$O$232='환불표 ver.1'!$H$5)*($P$3:$P$232='환불표 ver.1'!$J$5) -> 0 | O13: 100시간권 | P13: 10 | Q13: =Q12-1500 -> 80000
B14: =--($C$4:$C$115='환불표 ver.1'!$B$5)*($D$4:$D$115='환불표 ver.1'!$D$5) -> 0 | C14: 2주권 | D14: 11 | E14: 0 | N14: =--($O$3:$O$232='환불표 ver.1'!$H$5)*($P$3:$P$232='환불표 ver.1'!$J$5) -> 0 | O14: 100시간권 | P14: 11 | Q14: =Q13-1500 -> 78500
B15: =--($C$4:$C$115='환불표 ver.1'!$B$5)*($D$4:$D$115='환불표 ver.1'!$D$5) -> 0 | C15: 2주권 | D15: 12 | E15: 0 | N15: =--($O$3:$O$232='환불표 ver.1'!$H$5)*($P$3:$P$232='환불표 ver.1'!$J$5) -> 0 | O15: 100시간권 | P15: 12 | Q15: =Q14-1500 -> 77000
B16: =--($C$4:$C$115='환불표 ver.1'!$B$5)*($D$4:$D$115='환불표 ver.1'!$D$5) -> 0 | C16: 2주권 | D16: 13 | E16: 0 | N16: =--($O$3:$O$232='환불표 ver.1'!$H$5)*($P$3:$P$232='환불표 ver.1'!$J$5) -> 0 | O16: 100시간권 | P16: 13 | Q16: =Q15-1500 -> 75500
B17: =--($C$4:$C$115='환불표 ver.1'!$B$5)*($D$4:$D$115='환불표 ver.1'!$D$5) -> 0 | C17: 2주권 | D17: 14 | E17: 0 | N17: =--($O$3:$O$232='환불표 ver.1'!$H$5)*($P$3:$P$232='환불표 ver.1'!$J$5) -> 0 | O17: 100시간권 | P17: 14 | Q17: =Q16-1500 -> 74000
B18: =--($C$4:$C$115='환불표 ver.1'!$B$5)*($D$4:$D$115='환불표 ver.1'!$D$5) -> 0 | C18: 2주권 | D18: 15 | E18: 0 | N18: =--($O$3:$O$232='환불표 ver.1'!$H$5)*($P$3:$P$232='환불표 ver.1'!$J$5) -> 0 | O18: 100시간권 | P18: 15 | Q18: =Q17-1500 -> 72500
B19: =--($C$4:$C$115='환불표 ver.1'!$B$5)*($D$4:$D$115='환불표 ver.1'!$D$5) -> 0 | C19: 2주권 | D19: 16 | E19: 0 | N19: =--($O$3:$O$232='환불표 ver.1'!$H$5)*($P$3:$P$232='환불표 ver.1'!$J$5) -> 0 | O19: 100시간권 | P19: 16 | Q19: =Q18-1500 -> 71000
B20: =--($C$4:$C$115='환불표 ver.1'!$B$5)*($D$4:$D$115='환불표 ver.1'!$D$5) -> 0 | C20: 2주권 | D20: 17 | E20: 0 | N20: =--($O$3:$O$232='환불표 ver.1'!$H$5)*($P$3:$P$232='환불표 ver.1'!$J$5) -> 0 | O20: 100시간권 | P20: 17 | Q20: =Q19-1500 -> 69500
B21: =--($C$4:$C$115='환불표 ver.1'!$B$5)*($D$4:$D$115='환불표 ver.1'!$D$5) -> 0 | C21: 2주권 | D21: 18 | E21: 0 | N21: =--($O$3:$O$232='환불표 ver.1'!$H$5)*($P$3:$P$232='환불표 ver.1'!$J$5) -> 0 | O21: 100시간권 | P21: 18 | Q21: =Q20-1500 -> 68000
... B66: =--($C$4:$C$115='환불표 ver.1'!$B$5)*($D$4:$D$115='환불표 ver.1'!$D$5) -> 0 | C66: 고정석 4주권 | D66: 7 | E66: 125300 | N66: =--($O$3:$O$232='환불표 ver.1'!$H$5)*($P$3:$P$232='환불표 ver.1'!$J$5) -> 0 | O66: 100시간권 | P66: 63 | Q66: =Q65-1500 -> 500
B67: =--($C$4:$C$115='환불표 ver.1'!$B$5)*($D$4:$D$115='환불표 ver.1'!$D$5) -> 0 | C67: 고정석 4주권 | D67: 8 | E67: 71600 | N67: =--($O$3:$O$232='환불표 ver.1'!$H$5)*($P$3:$P$232='환불표 ver.1'!$J$5) -> 0 | O67: 200시간권 | P67: 0 | Q67: 180000
B68: =--($C$4:$C$115='환불표 ver.1'!$B$5)*($D$4:$D$115='환불표 ver.1'!$D$5) -> 0 | C68: 고정석 4주권 | D68: 9 | E68: 71600 | N68: =--($O$3:$O$232='환불표 ver.1'!$H$5)*($P$3:$P$232='환불표 ver.1'!$J$5) -> 0 | O68: 200시간권 | P68: 1 | Q68: =Q67-1500 -> 178500
B69: =--($C$4:$C$115='환불표 ver.1'!$B$5)*($D$4:$D$115='환불표 ver.1'!$D$5) -> 0 | C69: 고정석 4주권 | D69: 10 | E69: 71600 | N69: =--($O$3:$O$232='환불표 ver.1'!$H$5)*($P$3:$P$232='환불표 ver.1'!$J$5) -> 0 | O69: 200시간권 | P69: 2 | Q69: =Q68-1500 -> 177000
B70: =--($C$4:$C$115='환불표 ver.1'!$B$5)*($D$4:$D$115='환불표 ver.1'!$D$5) -> 0 | C70: 고정석 4주권 | D70: 11 | E70: 71600 | N70: =--($O$3:$O$232='환불표 ver.1'!$H$5)*($P$3:$P$232='환불표 ver.1'!$J$5) -> 0 | O70: 200시간권 | P70: 3 | Q70: =Q69-1500 -> 175500
B71: =--($C$4:$C$115='환불표 ver.1'!$B$5)*($D$4:$D$115='환불표 ver.1'!$D$5) -> 0 | C71: 고정석 4주권 | D71: 12 | E71: 71600 | N71: =--($O$3:$O$232='환불표 ver.1'!$H$5)*($P$3:$P$232='환불표 ver.1'!$J$5) -> 0 | O71: 200시간권 | P71: 4 | Q71: =Q70-1500 -> 174000
B72: =--($C$4:$C$115='환불표 ver.1'!$B$5)*($D$4:$D$115='환불표 ver.1'!$D$5) -> 0 | C72: 고정석 4주권 | D72: 13 | E72: 71600 | N72: =--($O$3:$O$232='환불표 ver.1'!$H$5)*($P$3:$P$232='환불표 ver.1'!$J$5) -> 0 | O72: 200시간권 | P72: 5 | Q72: =Q71-1500 -> 172500
B73: =--($C$4:$C$115='환불표 ver.1'!$B$5)*($D$4:$D$115='환불표 ver.1'!$D$5) -> 0 | C73: 고정석 4주권 | D73: 14 | E73: 71600 | N73: =--($O$3:$O$232='환불표 ver.1'!$H$5)*($P$3:$P$232='환불표 ver.1'!$J$5) -> 0 | O73: 200시간권 | P73: 6 | Q73: =Q72-1500 -> 171000
B74: =--($C$4:$C$115='환불표 ver.1'!$B$5)*($D$4:$D$115='환불표 ver.1'!$D$5) -> 0 | C74: 고정석 4주권 | D74: 15 | E74: 35800 | N74: =--($O$3:$O$232='환불표 ver.1'!$H$5)*($P$3:$P$232='환불표 ver.1'!$J$5) -> 0 | O74: 200시간권 | P74: 7 | Q74: =Q73-1500 -> 169500
B75: =--($C$4:$C$115='환불표 ver.1'!$B$5)*($D$4:$D$115='환불표 ver.1'!$D$5) -> 0 | C75: 고정석 4주권 | D75: 16 | E75: 35800 | N75: =--($O$3:$O$232='환불표 ver.1'!$H$5)*($P$3:$P$232='환불표 ver.1'!$J$5) -> 0 | O75: 200시간권 | P75: 8 | Q75: =Q74-1500 -> 168000
B76: =--($C$4:$C$115='환불표 ver.1'!$B$5)*($D$4:$D$115='환불표 ver.1'!$D$5) -> 0 | C76: 고정석 4주권 | D76: 17 | E76: 35800 | N76: =--($O$3:$O$232='환불표 ver.1'!$H$5)*($P$3:$P$232='환불표 ver.1'!$J$5) -> 0 | O76: 200시간권 | P76: 9 | Q76: =Q75-1500 -> 166500
B77: =--($C$4:$C$115='환불표 ver.1'!$B$5)*($D$4:$D$115='환불표 ver.1'!$D$5) -> 0 | C77: 고정석 4주권 | D77: 18 | E77: 35800 | N77: =--($O$3:$O$232='환불표 ver.1'!$H$5)*($P$3:$P$232='환불표 ver.1'!$J$5) -> 0 | O77: 200시간권 | P77: 10 | Q77: =Q76-1500 -> 165000
B78: =--($C$4:$C$115='환불표 ver.1'!$B$5)*($D$4:$D$115='환불표 ver.1'!$D$5) -> 0 | C78: 고정석 4주권 | D78: 19 | E78: 35800 | N78: =--($O$3:$O$232='환불표 ver.1'!$H$5)*($P$3:$P$232='환불표 ver.1'!$J$5) -> 0 | O78: 200시간권 | P78: 11 | Q78: =Q77-1500 -> 163500
B79: =--($C$4:$C$115='환불표 ver.1'!$B$5)*($D$4:$D$115='환불표 ver.1'!$D$5) -> 0 | C79: 고정석 4주권 | D79: 20 | E79: 35800 | N79: =--($O$3:$O$232='환불표 ver.1'!$H$5)*($P$3:$P$232='환불표 ver.1'!$J$5) -> 0 | O79: 200시간권 | P79: 12 | Q79: =Q78-1500 -> 162000
... B115: =--($C$4:$C$115='환불표 ver.1'!$B$5)*($D$4:$D$115='환불표 ver.1'!$D$5) -> 0 | C115: 관리고정석 4주권 | D115: 28 | E115: 0 | N115: =--($O$3:$O$232='환불표 ver.1'!$H$5)*($P$3:$P$232='환불표 ver.1'!$J$5) -> 0 | O115: 200시간권 | P115: 48 | Q115: =Q114-1500 -> 108000
B116: =--($C$4:$C$143='환불표 ver.1'!$B$5)*($D$4:$D$143='환불표 ver.1'!$D$5) -> 0 | C116: 오픈행사 4주권 | D116: 1 | E116: 55300 | N116: =--($O$3:$O$232='환불표 ver.1'!$H$5)*($P$3:$P$232='환불표 ver.1'!$J$5) -> 0 | O116: 200시간권 | P116: 49 | Q116: =Q115-1500 -> 106500
B117: =--($C$4:$C$143='환불표 ver.1'!$B$5)*($D$4:$D$143='환불표 ver.1'!$D$5) -> 0 | C117: 오픈행사 4주권 | D117: 2 | E117: 55300 | N117: =--($O$3:$O$232='환불표 ver.1'!$H$5)*($P$3:$P$232='환불표 ver.1'!$J$5) -> 0 | O117: 200시간권 | P117: 50 | Q117: =Q116-1500 -> 105000
B118: =--($C$4:$C$143='환불표 ver.1'!$B$5)*($D$4:$D$143='환불표 ver.1'!$D$5) -> 0 | C118: 오픈행사 4주권 | D118: 3 | E118: 55300 | N118: =--($O$3:$O$232='환불표 ver.1'!$H$5)*($P$3:$P$232='환불표 ver.1'!$J$5) -> 0 | O118: 200시간권 | P118: 51 | Q118: =Q117-1500 -> 103500
B119: =--($C$4:$C$143='환불표 ver.1'!$B$5)*($D$4:$D$143='환불표 ver.1'!$D$5) -> 0 | C119: 오픈행사 4주권 | D119: 4 | E119: 55300 | N119: =--($O$3:$O$232='환불표 ver.1'!$H$5)*($P$3:$P$232='환불표 ver.1'!$J$5) -> 0 | O119: 200시간권 | P119: 52 | Q119: =Q118-1500 -> 102000
B120: =--($C$4:$C$143='환불표 ver.1'!$B$5)*($D$4:$D$143='환불표 ver.1'!$D$5) -> 0 | C120: 오픈행사 4주권 | D120: 5 | E120: 55300 | N120: =--($O$3:$O$232='환불표 ver.1'!$H$5)*($P$3:$P$232='환불표 ver.1'!$J$5) -> 0 | O120: 200시간권 | P120: 53 | Q120: =Q119-1500 -> 100500
...

Sheet Sheet2
A1: 구 분 | B1: 1주차 | C1: 2주차 | D1: 3주차 | E1: 4주차 | F1: 5주차 | G1: 6주차 | H1: 7주차 | I1: 8주차 | J1: 9주차 | K1: 10주차 | L1: 11주차 | M1: 12주차 | N1: 13주차 | O1: 14주차 | P1: 15주차 | Q1: 16주차 | R1: 17주차 | S1: 18주차 | T1: 19주차 | U1: 20주차
A2: 2주권 | B2: 0.4
A3: 4주권 | B3: 0.7 | C3: 0.4 | D3: 0.2
A4: 5주권 | B4: 0.7 | C4: 0.4 | D4: 0.2 | E4: 0.2
A5: 6주권 | B5: 0.7 | C5: 0.4 | D5: 0.4 | E5: 0.2 | F5: 0.2
A6: 7주권 | B6: 0.7 | C6: 0.7 | D6: 0.4 | E6: 0.4 | F6: 0.2 | G6: 0.2
A7: 8주권 | B7: 0.7 | C7: 0.7 | D7: 0.4 | E7: 0.4 | F7: 0.2 | G7: 0.2 | H7: 0.2
A8: 9주권 | B8: 0.7 | C8: 0.7 | D8: 0.4 | E8: 0.4 | F8: 0.4 | G8: 0.2 | H8: 0.2 | I8: 0.2
A9: 10주권 | B9: 0.7 | C9: 0.7 | D9: 0.4 | E9: 0.4 | F9: 0.4 | G9: 0.2 | H9: 0.2 | I9: 0.2 | J9: 0.2
A10: 11주권 | B10: 0.7 | C10: 0.7 | D10: 0.4 | E10: 0.4 | F10: 0.4 | G10: 0.4 | H10: 0.2 | I10: 0.2 | J10: 0.2
A11: 12주권 | B11: 0.7 | C11: 0.7 | D11: 0.7 | E11: 0.4 | F11: 0.4 | G11: 0.4 | H11: 0.2 | I11: 0.2 | J11: 0.2
A12: 13주권 | B12: 0.7 | C12: 0.7 | D12: 0.7 | E12: 0.4 | F12: 0.4 | G12: 0.4 | H12: 0.2 | I12: 0.2 | J12: 0.2 | K12: 0.2
A13: 14주권 | B13: 0.7 | C13: 0.7 | D13: 0.7 | E13: 0.4 | F13: 0.4 | G13: 0.4 | H13: 0.4 | I13: 0.2 | J13: 0.2 | K13: 0.2 | L13: 0.2
A14: 15주권 | B14: 0.7 | C14: 0.7 | D14: 0.7 | E14: 0.7 | F14: 0.4 | G14: 0.4 | H14: 0.4 | I14: 0.4 | J14: 0.2 | K14: 0.2 | L14: 0.2 | M14: 0.2
A15: 16주권 | B15: 0.7 | C15: 0.7 | D15: 0.7 | E15: 0.7 | F15: 0.4 | G15: 0.4 | H15: 0.4 | I15: 0.4 | J15: 0.2 | K15: 0.2 | L15: 0.2 | M15: 0.2 | N15: 0.2
A16: 17주권 | B16: 0.7 | C16: 0.7 | D16: 0.7 | E16: 0.7 | F16: 0.4 | G16: 0.4 | H16: 0.4 | I16: 0.4 | J16: 0.4 | K16: 0.2 | L16: 0.2 | M16: 0.2 | N16: 0.2 | O16: 0.2
A17: 18주권 | B17: 0.7 | C17: 0.7 | D17: 0.7 | E17: 0.7 | F17: 0.4 | G17: 0.4 | H17: 0.4 | I17: 0.4 | J17: 0.4 | K17: 0.4 | L17: 0.2 | M17: 0.2 | N17: 0.2 | O17: 0.2 | P17: 0.2
A18: 19주권 | B18: 0.7 | C18: 0.7 | D18: 0.7 | E18: 0.7 | F18: 0.7 | G18: 0.4 | H18: 0.4 | I18: 0.4 | J18: 0.4 | K18: 0.4 | L18: 0.2 | M18: 0.2 | N18: 0.2 | O18: 0.2 | P18: 0.2 | Q18: 0.2
A19: 20주권 | B19: 0.7 | C19: 0.7 | D19: 0.7 | E19: 0.7 | F19: 0.7 | G19: 0.4 | H19: 0.4 | I19: 0.4 | J19: 0.4 | K19: 0.4 | L19: 0.2 | M19: 0.2 | N19: 0.2 | O19: 0.2 | P19: 0.2 | Q19: 0.2
